Workbook
Name Price: 'Valuation'!$D$194
Name AsOfQuarter: 'Valuation'!$D$195
Name Shares: 'Valuation'!$D$196
Name SharesDiluted: 'Valuation'!$D$197
Name NetDebt: 'Valuation'!$D$198
Name Base_EBITDA: 'Valuation'!$D$199
Name Adj_EBITDA: 'Valuation'!$D$200
Name FCF_TTM: 'Valuation'!$D$201
Name Adj_FCF_TTM: 'Valuation'!$D$202
Name Revenue_TTM: 'Valuation'!$D$203
Name EPS_TTM: 'Valuation'!$D$204
Name Adj_EPS_TTM: 'Valuation'!$D$205
Name BV_PerShare: 'Valuation'!$D$206
Name TBV_PerShare: 'Valuation'!$D$207
Name Target_EV_AdjEBITDA: 'Valuation'!$D$208
Name Target_EV_EBITDA: 'Valuation'!$D$209
Name Target_EV_Yield: 'Valuation'!$D$210
Name Capex_TTM: 'Valuation'!$D$211
Name InterestPaid_TTM: 'Valuation'!$D$212
Name MaintCapexRatio: 'Valuation'!$D$213
Name RecurringCashCosts: 'Valuation'!$D$214
Name WCNormalization: 'Valuation'!$D$215
Name PerShareMode: 'Valuation'!$D$216
Name CompanyOperatingMargin_Latest: 'Valuation'!$M$14
Name OperatingMargin_Latest: 'Valuation'!$M$14
Name CompanyOperatingMargin_TTM: 'Valuation'!$M$15
Name MarketCap: 'Valuation'!$N$194
Name EV: 'Valuation'!$N$195
Name Implied_EV_AdjEBITDA: 'Valuation'!$N$196
Name Implied_EV_EBITDA: 'Valuation'!$N$197
Name FCFF_Proxy_TTM: 'Valuation'!$N$198
Name Implied_FCFF_Yield: 'Valuation'!$N$199
Name Equity_FCF_Yield: 'Valuation'!$N$200
Name OwnerEarnings_TTM: 'Valuation'!$N$201
Name OwnerEarnings_Yield: 'Valuation'!$N$202
Name EqShare_Target_Adj: 'Valuation'!$N$203
Name EqShare_Target_EV: 'Valuation'!$N$204
Name EqShare_Target_Yield: 'Valuation'!$N$205
Name AutoImpliedGT: 'Valuation'!$R$234
Name ImpliedGT_WACC: 'Valuation'!$P$223:$P$230
Name ImpliedGT_Output: 'Valuation'!$Q$223:$Q$230
Name ImpliedGT_Status: 'Valuation'!$S$223:$S$230
Name calculation_history_quarterly_rows: 'History_Q'!$A$2
Name summary_company_description: 'SUMMARY'!$A$3
Name summary_key_advantage: 'SUMMARY'!$A$7
Name summary_strategic_context: 'SUMMARY'!$A$5
Name summary_revenue_stream_rows: 'SUMMARY'!$A$9
Name summary_segment_model: 'SUMMARY'!$A$13
Name summary_key_risks: 'SUMMARY'!$A$17
Name summary_wrong_if: 'SUMMARY'!$A$23
Name summary_as_of_quarter: 'SUMMARY'!$B$26
Name summary_latest_net_income: 'SUMMARY'!$B$30
Name summary_net_leverage: 'SUMMARY'!$B$41
Name valuation_guidance_current_primary_rows: 'Valuation'!$O$9
Name valuation_guidance_historical_rows: 'Valuation'!$O$29
Name valuation_guidance_current_secondary_rows: 'Valuation'!$O$16
Name valuation_thesis_debate_rows: 'Valuation'!$O$51
Name bs_segment_quarterly_rows: 'BS_Segments'!$A$61
Name bs_segment_annual_rows: 'BS_Segments'!$A$72
Name od_watchlist_rows: 'Operating_Drivers'!$A$6

Sheet SUMMARY
A1: SUMMARY
A2: What the company does
A4: Current strategic context
A6: Key competitive advantage
A12: Operating model per segment
A16: Key dependencies (3-5)
A22: What would make me wrong
A25: Key Financials
A26: As of quarter
A27: Revenue TTM ($m) | B27: =IFERROR(IF(OR($B$26="",COUNTIF('Valuation'!$B$6:$M$6,$B$26)<>1,NOT(ISNUMBER(INDEX('Valuation'!$B$10:$M$10,1,MATCH($B$26,'Valuation'!$B$6:$M$6,0))))),"",INDEX('Valuation'!$B$10:$M$10,1,MATCH($B$26,'Valuation'!$B$6:$M$6,0))),"")
A28: Revenue, latest quarter ($m)
A29: Revenue growth YoY, latest quarter (%) | B29: =IFERROR(IF(OR($B$26="",COUNTIF('Valuation'!$B$6:$M$6,$B$26)<>1,NOT(ISNUMBER(INDEX('Valuation'!$B$11:$M$11,1,MATCH($B$26,'Valuation'!$B$6:$M$6,0))))),"",INDEX('Valuation'!$B$11:$M$11,1,MATCH($B$26,'Valuation'!$B$6:$M$6,0))),"")
A30: Net income, latest quarter ($m)
A31: Net income growth YoY, latest quarter (%) | B31: =IFERROR(IF(OR($B$26="",COUNTIF('Valuation'!$B$6:$M$6,$B$26)<>1,NOT(ISNUMBER(INDEX('Valuation'!$B$38:$M$38,1,MATCH($B$26,'Valuation'!$B$6:$M$6,0))))),"",INDEX('Valuation'!$B$38:$M$38,1,MATCH($B$26,'Valuation'!$B$6:$M$6,0))),"")
A32: GAAP diluted EPS ($/share) | B32: =IFERROR(IF(OR($B$26="",COUNTIF('Valuation'!$B$6:$M$6,$B$26)<>1,NOT(ISNUMBER(INDEX('Valuation'!$B$107:$M$107,1,MATCH($B$26,'Valuation'!$B$6:$M$6,0))))),"",INDEX('Valuation'!$B$107:$M$107,1,MATCH($B$26,'Valuation'!$B$6:$M$6,0))),"")
A33: GAAP diluted EPS growth YoY (%) | B33: =IFERROR(IF(OR($B$26="",COUNTIF('Valuation'!$B$6:$M$6,$B$26)<>1,NOT(ISNUMBER(INDEX('Valuation'!$B$108:$M$108,1,MATCH($B$26,'Valuation'!$B$6:$M$6,0))))),"",INDEX('Valuation'!$B$108:$M$108,1,MATCH($B$26,'Valuation'!$B$6:$M$6,0))),"")
A34: Total debt, latest quarter ($m) | B34: N/A
A35: Debt-to-equity, latest quarter (x) | B35: N/A
A36: FCF TTM ($m) | B36: =IFERROR(IF(OR($B$26="",COUNTIF('Valuation'!$B$6:$M$6,$B$26)<>1,NOT(ISNUMBER(INDEX('Valuation'!$B$49:$M$49,1,MATCH($B$26,'Valuation'!$B$6:$M$6,0))))),"",INDEX('Valuation'!$B$49:$M$49,1,MATCH($B$26,'Valuation'!$B$6:$M$6,0))),"")
A37: FCF growth YoY, latest quarter (%) | B37: =IFERROR(IF(OR($B$26="",COUNTIF('Valuation'!$B$6:$M$6,$B$26)<>1,MATCH($B$26,'Valuation'!$B$6:$M$6,0)<=4,NOT(ISNUMBER(INDEX('Valuation'!$B$48:$M$48,1,MATCH($B$26,'Valuation'!$B$6:$M$6,0)))),NOT(ISNUMBER(INDEX('Valuation'!$B$47:$M$47,1,MATCH($B$26,'Valuation'!$B$6:$M$6,0)-4))),INDEX('Valuation'!$B$47:$M$47,1,MATCH($B$26,'Valuation'!$B$6:$M$6,0)-4)=0),"",INDEX('Valuation'!$B$48:$M$48,1,MATCH($B$26,'Valuation'!$B$6:$M$6,0))/ABS(INDEX('Valuation'!$B$47:$M$47,1,MATCH($B$26,'Valuation'!$B$6:$M$6,0)-4))),"")
A38: P/E, price-linked (x) | B38: N/A
A39: P/S, price-linked (x) | B39: N/A
A40: Leverage / Liquidity
A41: Net leverage (x)
A42: Interest coverage, P&L TTM (x) | B42: =IFERROR(IF(OR($B$26="",COUNTIF('Valuation'!$B$6:$M$6,$B$26)<>1,NOT(ISNUMBER(INDEX('Valuation'!$B$88:$M$88,1,MATCH($B$26,'Valuation'!$B$6:$M$6,0))))),"",INDEX('Valuation'!$B$88:$M$88,1,MATCH($B$26,'Valuation'!$B$6:$M$6,0))),"")
A43: Interest coverage, cash TTM (x) | B43: N/A
A44: Revolver availability ($m)
A45: Total liquidity ($m)

Sheet Valuation
A1: Scale | B1: $m | C1: <=-15% | D1: -15..-5 | E1: -5..+5 | F1: +5..+15 | G1: >=+15%
A2: Values scaled to $m unless %
A3: Valuation
A4: QA: Revenue, EBITDA, CFO, Capex, Cash
B5: Actuals
A6: Quarter
A7: Operating | O7: Current guidance
A8: Top line | O8: Metric | Q8: Stated in | R8: Applies to | S8: Guidance | X8: Unit | Y8: Published | Z8: Evidence | AA8: Role / source status
A9: Revenue
A10: Revenue (TTM) | B10: =IF(OR(B$6="",COUNTIFS(History_Q!$C$2:$C$1000,"revenue",History_Q!$B$2:$B$1000,">="&((SUMIFS(History_Q!$B$2:$B$1000,History_Q!$A$2:$A$1000,B$6,History_Q!$C$2:$C$1000,"revenue"))-3),History_Q!$B$2:$B$1000,"<="&(SUMIFS(History_Q!$B$2:$B$1000,History_Q!$A$2:$A$1000,B$6,History_Q!$C$2:$C$1000,"revenue")),History_Q!$E$2:$E$1000,"$m",History_Q!$G$2:$G$1000,"populated")<>4,_xlfn.MAXIFS(History_Q!$B$2:$B$1000,History_Q!$C$2:$C$1000,"revenue",History_Q!$B$2:$B$1000,">="&((SUMIFS(History_Q!$B$2:$B$1000,History_Q!$A$2:$A$1000,B$6,History_Q!$C$2:$C$1000,"revenue"))-3),History_Q!$B$2:$B$1000,"<="&(SUMIFS(History_Q!$B$2:$B$1000,History_Q!$A$2:$A$1000,B$6,History_Q!$C$2:$C$1000,"revenue")),History_Q!$E$2:$E$1000,"$m",History_Q!$G$2:$G$1000,"populated")-_xlfn.MINIFS(History_Q!$B$2:$B$1000,History_Q!$C$2:$C$1000,"revenue",History_Q!$B$2:$B$1000,">="&((SUMIFS(History_Q!$B$2:$B$1000,History_Q!$A$2:$A$1000,B$6,History_Q!$C$2:$C$1000,"revenue"))-3),History_Q!$B$2:$B$1000,"<="&(SUMIFS(History_Q!$B$2:$B$1000,History_Q!$A$2:$A$1000,B$6,History_Q!$C$2:$C$1000,"revenue")),History_Q!$E$2:$E$1000,"$m",History_Q!$G$2:$G$1000,"populated")<>3),"",SUMIFS(History_Q!$D$2:$D$1000,History_Q!$C$2:$C$1000,"revenue",History_Q!$B$2:$B$1000,">="&((SUMIFS(History_Q!$B$2:$B$1000,History_Q!$A$2:$A$1000,B$6,History_Q!$C$2:$C$1000,"revenue"))-3),History_Q!$B$2:$B$1000,"<="&(SUMIFS(History_Q!$B$2:$B$1000,History_Q!$A$2:$A$1000,B$6,History_Q!$C$2:$C$1000,"revenue")),History_Q!$E$2:$E$1000,"$m",History_Q!$G$2:$G$1000,"populated")) | C10: =IF(OR(C$6="",COUNTIFS(History_Q!$C$2:$C$1000,"revenue",History_Q!$B$2:$B$1000,">="&((SUMIFS(History_Q!$B$2:$B$1000,History_Q!$A$2:$A$1000,C$6,History_Q!$C$2:$C$1000,"revenue"))-3),History_Q!$B$2:$B$1000,"<="&(SUMIFS(History_Q!$B$2:$B$1000,History_Q!$A$2:$A$1000,C$6,History_Q!$C$2:$C$1000,"revenue")),History_Q!$E$2:$E$1000,"$m",History_Q!$G$2:$G$1000,"populated")<>4,_xlfn.MAXIFS(History_Q!$B$2:$B$1000,History_Q!$C$2:$C$1000,"revenue",History_Q!$B$2:$B$1000,">="&((SUMIFS(History_Q!$B$2:$B$1000,History_Q!$A$2:$A$1000,C$6,History_Q!$C$2:$C$1000,"revenue"))-3),History_Q!$B$2:$B$1000,"<="&(SUMIFS(History_Q!$B$2:$B$1000,History_Q!$A$2:$A$1000,C$6,History_Q!$C$2:$C$1000,"revenue")),History_Q!$E$2:$E$1000,"$m",History_Q!$G$2:$G$1000,"populated")-_xlfn.MINIFS(History_Q!$B$2:$B$1000,History_Q!$C$2:$C$1000,"revenue",History_Q!$B$2:$B$1000,">="&((SUMIFS(History_Q!$B$2:$B$1000,History_Q!$A$2:$A$1000,C$6,History_Q!$C$2:$C$1000,"revenue"))-3),History_Q!$B$2:$B$1000,"<="&(SUMIFS(History_Q!$B$2:$B$1000,History_Q!$A$2:$A$1000,C$6,History_Q!$C$2:$C$1000,"revenue")),History_Q!$E$2:$E$1000,"$m",History_Q!$G$2:$G$1000,"populated")<>3),"",SUMIFS(History_Q!$D$2:$D$1000,History_Q!$C$2:$C$1000,"revenue",History_Q!$B$2:$B$1000,">="&((SUMIFS(History_Q!$B$2:$B$1000,History_Q!$A$2:$A$1000,C$6,History_Q!$C$2:$C$1000,"revenue"))-3),History_Q!$B$2:$B$1000,"<="&(SUMIFS(History_Q!$B$2:$B$1000,History_Q!$A$2:$A$1000,C$6,History_Q!$C$2:$C$1000,"revenue")),History_Q!$E$2:$E$1000,"$m",History_Q!$G$2:$G$1000,"populated")) | D10: =IF(OR(D$6="",COUNTIFS(History_Q!$C$2:$C$1000,"revenue",History_Q!$B$2:$B$1000,">="&((SUMIFS(History_Q!$B$2:$B$1000,History_Q!$A$2:$A$1000,D$6,History_Q!$C$2:$C$1000,"revenue"))-3),History_Q!$B$2:$B$1000,"<="&(SUMIFS(History_Q!$B$2:$B$1000,History_Q!$A$2:$A$1000,D$6,History_Q!$C$2:$C$1000,"revenue")),History_Q!$E$2:$E$1000,"$m",History_Q!$G$2:$G$1000,"populated")<>4,_xlfn.MAXIFS(History_Q!$B$2:$B$1000,History_Q!$C$2:$C$1000,"revenue",History_Q!$B$2:$B$1000,">="&((SUMIFS(History_Q!$B$2:$B$1000,History_Q!$A$2:$A$1000,D$6,History_Q!$C$2:$C$1000,"revenue"))-3),History_Q!$B$2:$B$1000,"<="&(SUMIFS(History_Q!$B$2:$B$1000,History_Q!$A$2:$A$1000,D$6,History_Q!$C$2:$C$1000,"revenue")),History_Q!$E$2:$E$1000,"$m",History_Q!$G$2:$G$1000,"populated")-_xlfn.MINIFS(History_Q!$B$2:$B$1000,History_Q!$C$2:$C$1000,"revenue",History_Q!$B$2:$B$1000,">="&((SUMIFS(History_Q!$B$2:$B$1000,History_Q!$A$2:$A$1000,D$6,History_Q!$C$2:$C$1000,"revenue"))-3),History_Q!$B$2:$B$1000,"<="&(SUMIFS(History_Q!$B$2:$B$1000,History_Q!$A$2:$A$1000,D$6,History_Q!$C$2:$C$1000,"revenue")),History_Q!$E$2:$E$1000,"$m",History_Q!$G$2:$G$1000,"populated")<>3),"",SUMIFS(History_Q!$D$2:$D$1000,History_Q!$C$2:$C$1000,"revenue",History_Q!$B$2:$B$1000,">="&((SUMIFS(History_Q!$B$2:$B$1000,History_Q!$A$2:$A$1000,D$6,History_Q!$C$2:$C$1000,"revenue"))-3),History_Q!$B$2:$B$1000,"<="&(SUMIFS(History_Q!$B$2:$B$1000,History_Q!$A$2:$A$1000,D$6,History_Q!$C$2:$C$1000,"revenue")),History_Q!$E$2:$E$1000,"$m",History_Q!$G$2:$G$1000,"populated")) | E10: =IF(OR(E$6="",COUNTIFS(History_Q!$C$2:$C$1000,"revenue",History_Q!$B$2:$B$1000,">="&((SUMIFS(History_Q!$B$2:$B$1000,History_Q!$A$2:$A$1000,E$6,History_Q!$C$2:$C$1000,"revenue"))-3),History_Q!$B$2:$B$1000,"<="&(SUMIFS(History_Q!$B$2:$B$1000,History_Q!$A$2:$A$1000,E$6,History_Q!$C$2:$C$1000,"revenue")),History_Q!$E$2:$E$1000,"$m",History_Q!$G$2:$G$1000,"populated")<>4,_xlfn.MAXIFS(History_Q!$B$2:$B$1000,History_Q!$C$2:$C$1000,"revenue",History_Q!$B$2:$B$1000,">="&((SUMIFS(History_Q!$B$2:$B$1000,History_Q!$A$2:$A$1000,E$6,History_Q!$C$2:$C$1000,"revenue"))-3),History_Q!$B$2:$B$1000,"<="&(SUMIFS(History_Q!$B$2:$B$1000,History_Q!$A$2:$A$1000,E$6,History_Q!$C$2:$C$1000,"revenue")),History_Q!$E$2:$E$1000,"$m",History_Q!$G$2:$G$1000,"populated")-_xlfn.MINIFS(History_Q!$B$2:$B$1000,History_Q!$C$2:$C$1000,"revenue",History_Q!$B$2:$B$1000,">="&((SUMIFS(History_Q!$B$2:$B$1000,History_Q!$A$2:$A$1000,E$6,History_Q!$C$2:$C$1000,"revenue"))-3),History_Q!$B$2:$B$1000,"<="&(SUMIFS(History_Q!$B$2:$B$1000,History_Q!$A$2:$A$1000,E$6,History_Q!$C$2:$C$1000,"revenue")),History_Q!$E$2:$E$1000,"$m",History_Q!$G$2:$G$1000,"populated")<>3),"",SUMIFS(History_Q!$D$2:$D$1000,History_Q!$C$2:$C$1000,"revenue",History_Q!$B$2:$B$1000,">="&((SUMIFS(History_Q!$B$2:$B$1000,History_Q!$A$2:$A$1000,E$6,History_Q!$C$2:$C$1000,"revenue"))-3),History_Q!$B$2:$B$1000,"<="&(SUMIFS(History_Q!$B$2:$B$1000,History_Q!$A$2:$A$1000,E$6,History_Q!$C$2:$C$1000,"revenue")),History_Q!$E$2:$E$1000,"$m",History_Q!$G$2:$G$1000,"populated")) | F10: =IF(OR(F$6="",COUNTIFS(History_Q!$C$2:$C$1000,"revenue",History_Q!$B$2:$B$1000,">="&((SUMIFS(History_Q!$B$2:$B$1000,History_Q!$A$2:$A$1000,F$6,History_Q!$C$2:$C$1000,"revenue"))-3),History_Q!$B$2:$B$1000,"<="&(SUMIFS(History_Q!$B$2:$B$1000,History_Q!$A$2:$A$1000,F$6,History_Q!$C$2:$C$1000,"revenue")),History_Q!$E$2:$E$1000,"$m",History_Q!$G$2:$G$1000,"populated")<>4,_xlfn.MAXIFS(History_Q!$B$2:$B$1000,History_Q!$C$2:$C$1000,"revenue",History_Q!$B$2:$B$1000,">="&((SUMIFS(History_Q!$B$2:$B$1000,History_Q!$A$2:$A$1000,F$6,History_Q!$C$2:$C$1000,"revenue"))-3),History_Q!$B$2:$B$1000,"<="&(SUMIFS(History_Q!$B$2:$B$1000,History_Q!$A$2:$A$1000,F$6,History_Q!$C$2:$C$1000,"revenue")),History_Q!$E$2:$E$1000,"$m",History_Q!$G$2:$G$1000,"populated")-_xlfn.MINIFS(History_Q!$B$2:$B$1000,History_Q!$C$2:$C$1000,"revenue",History_Q!$B$2:$B$1000,">="&((SUMIFS(History_Q!$B$2:$B$1000,History_Q!$A$2:$A$1000,F$6,History_Q!$C$2:$C$1000,"revenue"))-3),History_Q!$B$2:$B$1000,"<="&(SUMIFS(History_Q!$B$2:$B$1000,History_Q!$A$2:$A$1000,F$6,History_Q!$C$2:$C$1000,"revenue")),History_Q!$E$2:$E$1000,"$m",History_Q!$G$2:$G$1000,"populated")<>3),"",SUMIFS(History_Q!$D$2:$D$1000,History_Q!$C$2:$C$1000,"revenue",History_Q!$B$2:$B$1000,">="&((SUMIFS(History_Q!$B$2:$B$1000,History_Q!$A$2:$A$1000,F$6,History_Q!$C$2:$C$1000,"revenue"))-3),History_Q!$B$2:$B$1000,"<="&(SUMIFS(History_Q!$B$2:$B$1000,History_Q!$A$2:$A$1000,F$6,History_Q!$C$2:$C$1000,"revenue")),History_Q!$E$2:$E$1000,"$m",History_Q!$G$2:$G$1000,"populated")) | G10: =IF(OR(G$6="",COUNTIFS(History_Q!$C$2:$C$1000,"revenue",History_Q!$B$2:$B$1000,">="&((SUMIFS(History_Q!$B$2:$B$1000,History_Q!$A$2:$A$1000,G$6,History_Q!$C$2:$C$1000,"revenue"))-3),History_Q!$B$2:$B$1000,"<="&(SUMIFS(History_Q!$B$2:$B$1000,History_Q!$A$2:$A$1000,G$6,History_Q!$C$2:$C$1000,"revenue")),History_Q!$E$2:$E$1000,"$m",History_Q!$G$2:$G$1000,"populated")<>4,_xlfn.MAXIFS(History_Q!$B$2:$B$1000,History_Q!$C$2:$C$1000,"revenue",History_Q!$B$2:$B$1000,">="&((SUMIFS(History_Q!$B$2:$B$1000,History_Q!$A$2:$A$1000,G$6,History_Q!$C$2:$C$1000,"revenue"))-3),History_Q!$B$2:$B$1000,"<="&(SUMIFS(History_Q!$B$2:$B$1000,History_Q!$A$2:$A$1000,G$6,History_Q!$C$2:$C$1000,"revenue")),History_Q!$E$2:$E$1000,"$m",History_Q!$G$2:$G$1000,"populated")-_xlfn.MINIFS(History_Q!$B$2:$B$1000,History_Q!$C$2:$C$1000,"revenue",History_Q!$B$2:$B$1000,">="&((SUMIFS(History_Q!$B$2:$B$1000,History_Q!$A$2:$A$1000,G$6,History_Q!$C$2:$C$1000,"revenue"))-3),History_Q!$B$2:$B$1000,"<="&(SUMIFS(History_Q!$B$2:$B$1000,History_Q!$A$2:$A$1000,G$6,History_Q!$C$2:$C$1000,"revenue")),History_Q!$E$2:$E$1000,"$m",History_Q!$G$2:$G$1000,"populated")<>3),"",SUMIFS(History_Q!$D$2:$D$1000,History_Q!$C$2:$C$1000,"revenue",History_Q!$B$2:$B$1000,">="&((SUMIFS(History_Q!$B$2:$B$1000,History_Q!$A$2:$A$1000,G$6,History_Q!$C$2:$C$1000,"revenue"))-3),History_Q!$B$2:$B$1000,"<="&(SUMIFS(History_Q!$B$2:$B$1000,History_Q!$A$2:$A$1000,G$6,History_Q!$C$2:$C$1000,"revenue")),History_Q!$E$2:$E$1000,"$m",History_Q!$G$2:$G$1000,"populated")) | H10: =IF(OR(H$6="",COUNTIFS(History_Q!$C$2:$C$1000,"revenue",History_Q!$B$2:$B$1000,">="&((SUMIFS(History_Q!$B$2:$B$1000,History_Q!$A$2:$A$1000,H$6,History_Q!$C$2:$C$1000,"revenue"))-3),History_Q!$B$2:$B$1000,"<="&(SUMIFS(History_Q!$B$2:$B$1000,History_Q!$A$2:$A$1000,H$6,History_Q!$C$2:$C$1000,"revenue")),History_Q!$E$2:$E$1000,"$m",History_Q!$G$2:$G$1000,"populated")<>4,_xlfn.MAXIFS(History_Q!$B$2:$B$1000,History_Q!$C$2:$C$1000,"revenue",History_Q!$B$2:$B$1000,">="&((SUMIFS(History_Q!$B$2:$B$1000,History_Q!$A$2:$A$1000,H$6,History_Q!$C$2:$C$1000,"revenue"))-3),History_Q!$B$2:$B$1000,"<="&(SUMIFS(History_Q!$B$2:$B$1000,History_Q!$A$2:$A$1000,H$6,History_Q!$C$2:$C$1000,"revenue")),History_Q!$E$2:$E$1000,"$m",History_Q!$G$2:$G$1000,"populated")-_xlfn.MINIFS(History_Q!$B$2:$B$1000,History_Q!$C$2:$C$1000,"revenue",History_Q!$B$2:$B$1000,">="&((SUMIFS(History_Q!$B$2:$B$1000,History_Q!$A$2:$A$1000,H$6,History_Q!$C$2:$C$1000,"revenue"))-3),History_Q!$B$2:$B$1000,"<="&(SUMIFS(History_Q!$B$2:$B$1000,History_Q!$A$2:$A$1000,H$6,History_Q!$C$2:$C$1000,"revenue")),History_Q!$E$2:$E$1000,"$m",History_Q!$G$2:$G$1000,"populated")<>3),"",SUMIFS(History_Q!$D$2:$D$1000,History_Q!$C$2:$C$1000,"revenue",History_Q!$B$2:$B$1000,">="&((SUMIFS(History_Q!$B$2:$B$1000,History_Q!$A$2:$A$1000,H$6,History_Q!$C$2:$C$1000,"revenue"))-3),History_Q!$B$2:$B$1000,"<="&(SUMIFS(History_Q!$B$2:$B$1000,History_Q!$A$2:$A$1000,H$6,History_Q!$C$2:$C$1000,"revenue")),History_Q!$E$2:$E$1000,"$m",History_Q!$G$2:$G$1000,"populated")) | I10: =IF(OR(I$6="",COUNTIFS(History_Q!$C$2:$C$1000,"revenue",History_Q!$B$2:$B$1000,">="&((SUMIFS(History_Q!$B$2:$B$1000,History_Q!$A$2:$A$1000,I$6,History_Q!$C$2:$C$1000,"revenue"))-3),History_Q!$B$2:$B$1000,"<="&(SUMIFS(History_Q!$B$2:$B$1000,History_Q!$A$2:$A$1000,I$6,History_Q!$C$2:$C$1000,"revenue")),History_Q!$E$2:$E$1000,"$m",History_Q!$G$2:$G$1000,"populated")<>4,_xlfn.MAXIFS(History_Q!$B$2:$B$1000,History_Q!$C$2:$C$1000,"revenue",History_Q!$B$2:$B$1000,">="&((SUMIFS(History_Q!$B$2:$B$1000,History_Q!$A$2:$A$1000,I$6,History_Q!$C$2:$C$1000,"revenue"))-3),History_Q!$B$2:$B$1000,"<="&(SUMIFS(History_Q!$B$2:$B$1000,History_Q!$A$2:$A$1000,I$6,History_Q!$C$2:$C$1000,"revenue")),History_Q!$E$2:$E$1000,"$m",History_Q!$G$2:$G$1000,"populated")-_xlfn.MINIFS(History_Q!$B$2:$B$1000,History_Q!$C$2:$C$1000,"revenue",History_Q!$B$2:$B$1000,">="&((SUMIFS(History_Q!$B$2:$B$1000,History_Q!$A$2:$A$1000,I$6,History_Q!$C$2:$C$1000,"revenue"))-3),History_Q!$B$2:$B$1000,"<="&(SUMIFS(History_Q!$B$2:$B$1000,History_Q!$A$2:$A$1000,I$6,History_Q!$C$2:$C$1000,"revenue")),History_Q!$E$2:$E$1000,"$m",History_Q!$G$2:$G$1000,"populated")<>3),"",SUMIFS(History_Q!$D$2:$D$1000,History_Q!$C$2:$C$1000,"revenue",History_Q!$B$2:$B$1000,">="&((SUMIFS(History_Q!$B$2:$B$1000,History_Q!$A$2:$A$1000,I$6,History_Q!$C$2:$C$1000,"revenue"))-3),History_Q!$B$2:$B$1000,"<="&(SUMIFS(History_Q!$B$2:$B$1000,History_Q!$A$2:$A$1000,I$6,History_Q!$C$2:$C$1000,"revenue")),History_Q!$E$2:$E$1000,"$m",History_Q!$G$2:$G$1000,"populated")) | ... M10: =IF(OR(M$6="",COUNTIFS(History_Q!$C$2:$C$1000,"revenue",History_Q!$B$2:$B$1000,">="&((SUMIFS(History_Q!$B$2:$B$1000,History_Q!$A$2:$A$1000,M$6,History_Q!$C$2:$C$1000,"revenue"))-3),History_Q!$B$2:$B$1000,"<="&(SUMIFS(History_Q!$B$2:$B$1000,History_Q!$A$2:$A$1000,M$6,History_Q!$C$2:$C$1000,"revenue")),History_Q!$E$2:$E$1000,"$m",History_Q!$G$2:$G$1000,"populated")<>4,_xlfn.MAXIFS(History_Q!$B$2:$B$1000,History_Q!$C$2:$C$1000,"revenue",History_Q!$B$2:$B$1000,">="&((SUMIFS(History_Q!$B$2:$B$1000,History_Q!$A$2:$A$1000,M$6,History_Q!$C$2:$C$1000,"revenue"))-3),History_Q!$B$2:$B$1000,"<="&(SUMIFS(History_Q!$B$2:$B$1000,History_Q!$A$2:$A$1000,M$6,History_Q!$C$2:$C$1000,"revenue")),History_Q!$E$2:$E$1000,"$m",History_Q!$G$2:$G$1000,"populated")-_xlfn.MINIFS(History_Q!$B$2:$B$1000,History_Q!$C$2:$C$1000,"revenue",History_Q!$B$2:$B$1000,">="&((SUMIFS(History_Q!$B$2:$B$1000,History_Q!$A$2:$A$1000,M$6,History_Q!$C$2:$C$1000,"revenue"))-3),History_Q!$B$2:$B$1000,"<="&(SUMIFS(History_Q!$B$2:$B$1000,History_Q!$A$2:$A$1000,M$6,History_Q!$C$2:$C$1000,"revenue")),History_Q!$E$2:$E$1000,"$m",History_Q!$G$2:$G$1000,"populated")<>3),"",SUMIFS(History_Q!$D$2:$D$1000,History_Q!$C$2:$C$1000,"revenue",History_Q!$B$2:$B$1000,">="&((SUMIFS(History_Q!$B$2:$B$1000,History_Q!$A$2:$A$1000,M$6,History_Q!$C$2:$C$1000,"revenue"))-3),History_Q!$B$2:$B$1000,"<="&(SUMIFS(History_Q!$B$2:$B$1000,History_Q!$A$2:$A$1000,M$6,History_Q!$C$2:$C$1000,"revenue")),History_Q!$E$2:$E$1000,"$m",History_Q!$G$2:$G$1000,"populated"))
A11: Revenue YoY % | B11: =IF(OR(B$6="",COUNTIFS(History_Q!$C$2:$C$1000,"revenue",History_Q!$B$2:$B$1000,(SUMIFS(History_Q!$B$2:$B$1000,History_Q!$A$2:$A$1000,B$6,History_Q!$C$2:$C$1000,"revenue")),History_Q!$E$2:$E$1000,"$m",History_Q!$G$2:$G$1000,"populated")<>1,COUNTIFS(History_Q!$C$2:$C$1000,"revenue",History_Q!$B$2:$B$1000,(SUMIFS(History_Q!$B$2:$B$1000,History_Q!$A$2:$A$1000,B$6,History_Q!$C$2:$C$1000,"revenue")-4),History_Q!$E$2:$E$1000,"$m",History_Q!$G$2:$G$1000,"populated")<>1,SUMIFS(History_Q!$D$2:$D$1000,History_Q!$C$2:$C$1000,"revenue",History_Q!$B$2:$B$1000,(SUMIFS(History_Q!$B$2:$B$1000,History_Q!$A$2:$A$1000,B$6,History_Q!$C$2:$C$1000,"revenue")-4),History_Q!$E$2:$E$1000,"$m",History_Q!$G$2:$G$1000,"populated")=0),"",SUMIFS(History_Q!$D$2:$D$1000,History_Q!$C$2:$C$1000,"revenue",History_Q!$B$2:$B$1000,(SUMIFS(History_Q!$B$2:$B$1000,History_Q!$A$2:$A$1000,B$6,History_Q!$C$2:$C$1000,"revenue")),History_Q!$E$2:$E$1000,"$m",History_Q!$G$2:$G$1000,"populated")/SUMIFS(History_Q!$D$2:$D$1000,History_Q!$C$2:$C$1000,"revenue",History_Q!$B$2:$B$1000,(SUMIFS(History_Q!$B$2:$B$1000,History_Q!$A$2:$A$1000,B$6,History_Q!$C$2:$C$1000,"revenue")-4),History_Q!$E$2:$E$1000,"$m",History_Q!$G$2:$G$1000,"populated")-1) | C11: =IF(OR(C$6="",COUNTIFS(History_Q!$C$2:$C$1000,"revenue",History_Q!$B$2:$B$1000,(SUMIFS(History_Q!$B$2:$B$1000,History_Q!$A$2:$A$1000,C$6,History_Q!$C$2:$C$1000,"revenue")),History_Q!$E$2:$E$1000,"$m",History_Q!$G$2:$G$1000,"populated")<>1,COUNTIFS(History_Q!$C$2:$C$1000,"revenue",History_Q!$B$2:$B$1000,(SUMIFS(History_Q!$B$2:$B$1000,History_Q!$A$2:$A$1000,C$6,History_Q!$C$2:$C$1000,"revenue")-4),History_Q!$E$2:$E$1000,"$m",History_Q!$G$2:$G$1000,"populated")<>1,SUMIFS(History_Q!$D$2:$D$1000,History_Q!$C$2:$C$1000,"revenue",History_Q!$B$2:$B$1000,(SUMIFS(History_Q!$B$2:$B$1000,History_Q!$A$2:$A$1000,C$6,History_Q!$C$2:$C$1000,"revenue")-4),History_Q!$E$2:$E$1000,"$m",History_Q!$G$2:$G$1000,"populated")=0),"",SUMIFS(History_Q!$D$2:$D$1000,History_Q!$C$2:$C$1000,"revenue",History_Q!$B$2:$B$1000,(SUMIFS(History_Q!$B$2:$B$1000,History_Q!$A$2:$A$1000,C$6,History_Q!$C$2:$C$1000,"revenue")),History_Q!$E$2:$E$1000,"$m",History_Q!$G$2:$G$1000,"populated")/SUMIFS(History_Q!$D$2:$D$1000,History_Q!$C$2:$C$1000,"revenue",History_Q!$B$2:$B$1000,(SUMIFS(History_Q!$B$2:$B$1000,History_Q!$A$2:$A$1000,C$6,History_Q!$C$2:$C$1000,"revenue")-4),History_Q!$E$2:$E$1000,"$m",History_Q!$G$2:$G$1000,"populated")-1) | D11: =IF(OR(D$6="",COUNTIFS(History_Q!$C$2:$C$1000,"revenue",History_Q!$B$2:$B$1000,(SUMIFS(History_Q!$B$2:$B$1000,History_Q!$A$2:$A$1000,D$6,History_Q!$C$2:$C$1000,"revenue")),History_Q!$E$2:$E$1000,"$m",History_Q!$G$2:$G$1000,"populated")<>1,COUNTIFS(History_Q!$C$2:$C$1000,"revenue",History_Q!$B$2:$B$1000,(SUMIFS(History_Q!$B$2:$B$1000,History_Q!$A$2:$A$1000,D$6,History_Q!$C$2:$C$1000,"revenue")-4),History_Q!$E$2:$E$1000,"$m",History_Q!$G$2:$G$1000,"populated")<>1,SUMIFS(History_Q!$D$2:$D$1000,History_Q!$C$2:$C$1000,"revenue",History_Q!$B$2:$B$1000,(SUMIFS(History_Q!$B$2:$B$1000,History_Q!$A$2:$A$1000,D$6,History_Q!$C$2:$C$1000,"revenue")-4),History_Q!$E$2:$E$1000,"$m",History_Q!$G$2:$G$1000,"populated")=0),"",SUMIFS(History_Q!$D$2:$D$1000,History_Q!$C$2:$C$1000,"revenue",History_Q!$B$2:$B$1000,(SUMIFS(History_Q!$B$2:$B$1000,History_Q!$A$2:$A$1000,D$6,History_Q!$C$2:$C$1000,"revenue")),History_Q!$E$2:$E$1000,"$m",History_Q!$G$2:$G$1000,"populated")/SUMIFS(History_Q!$D$2:$D$1000,History_Q!$C$2:$C$1000,"revenue",History_Q!$B$2:$B$1000,(SUMIFS(History_Q!$B$2:$B$1000,History_Q!$A$2:$A$1000,D$6,History_Q!$C$2:$C$1000,"revenue")-4),History_Q!$E$2:$E$1000,"$m",History_Q!$G$2:$G$1000,"populated")-1) | E11: =IF(OR(E$6="",COUNTIFS(History_Q!$C$2:$C$1000,"revenue",History_Q!$B$2:$B$1000,(SUMIFS(History_Q!$B$2:$B$1000,History_Q!$A$2:$A$1000,E$6,History_Q!$C$2:$C$1000,"revenue")),History_Q!$E$2:$E$1000,"$m",History_Q!$G$2:$G$1000,"populated")<>1,COUNTIFS(History_Q!$C$2:$C$1000,"revenue",History_Q!$B$2:$B$1000,(SUMIFS(History_Q!$B$2:$B$1000,History_Q!$A$2:$A$1000,E$6,History_Q!$C$2:$C$1000,"revenue")-4),History_Q!$E$2:$E$1000,"$m",History_Q!$G$2:$G$1000,"populated")<>1,SUMIFS(History_Q!$D$2:$D$1000,History_Q!$C$2:$C$1000,"revenue",History_Q!$B$2:$B$1000,(SUMIFS(History_Q!$B$2:$B$1000,History_Q!$A$2:$A$1000,E$6,History_Q!$C$2:$C$1000,"revenue")-4),History_Q!$E$2:$E$1000,"$m",History_Q!$G$2:$G$1000,"populated")=0),"",SUMIFS(History_Q!$D$2:$D$1000,History_Q!$C$2:$C$1000,"revenue",History_Q!$B$2:$B$1000,(SUMIFS(History_Q!$B$2:$B$1000,History_Q!$A$2:$A$1000,E$6,History_Q!$C$2:$C$1000,"revenue")),History_Q!$E$2:$E$1000,"$m",History_Q!$G$2:$G$1000,"populated")/SUMIFS(History_Q!$D$2:$D$1000,History_Q!$C$2:$C$1000,"revenue",History_Q!$B$2:$B$1000,(SUMIFS(History_Q!$B$2:$B$1000,History_Q!$A$2:$A$1000,E$6,History_Q!$C$2:$C$1000,"revenue")-4),History_Q!$E$2:$E$1000,"$m",History_Q!$G$2:$G$1000,"populated")-1) | F11: =IF(OR(F$6="",COUNTIFS(History_Q!$C$2:$C$1000,"revenue",History_Q!$B$2:$B$1000,(SUMIFS(History_Q!$B$2:$B$1000,History_Q!$A$2:$A$1000,F$6,History_Q!$C$2:$C$1000,"revenue")),History_Q!$E$2:$E$1000,"$m",History_Q!$G$2:$G$1000,"populated")<>1,COUNTIFS(History_Q!$C$2:$C$1000,"revenue",History_Q!$B$2:$B$1000,(SUMIFS(History_Q!$B$2:$B$1000,History_Q!$A$2:$A$1000,F$6,History_Q!$C$2:$C$1000,"revenue")-4),History_Q!$E$2:$E$1000,"$m",History_Q!$G$2:$G$1000,"populated")<>1,SUMIFS(History_Q!$D$2:$D$1000,History_Q!$C$2:$C$1000,"revenue",History_Q!$B$2:$B$1000,(SUMIFS(History_Q!$B$2:$B$1000,History_Q!$A$2:$A$1000,F$6,History_Q!$C$2:$C$1000,"revenue")-4),History_Q!$E$2:$E$1000,"$m",History_Q!$G$2:$G$1000,"populated")=0),"",SUMIFS(History_Q!$D$2:$D$1000,History_Q!$C$2:$C$1000,"revenue",History_Q!$B$2:$B$1000,(SUMIFS(History_Q!$B$2:$B$1000,History_Q!$A$2:$A$1000,F$6,History_Q!$C$2:$C$1000,"revenue")),History_Q!$E$2:$E$1000,"$m",History_Q!$G$2:$G$1000,"populated")/SUMIFS(History_Q!$D$2:$D$1000,History_Q!$C$2:$C$1000,"revenue",History_Q!$B$2:$B$1000,(SUMIFS(History_Q!$B$2:$B$1000,History_Q!$A$2:$A$1000,F$6,History_Q!$C$2:$C$1000,"revenue")-4),History_Q!$E$2:$E$1000,"$m",History_Q!$G$2:$G$1000,"populated")-1) | G11: =IF(OR(G$6="",COUNTIFS(History_Q!$C$2:$C$1000,"revenue",History_Q!$B$2:$B$1000,(SUMIFS(History_Q!$B$2:$B$1000,History_Q!$A$2:$A$1000,G$6,History_Q!$C$2:$C$1000,"revenue")),History_Q!$E$2:$E$1000,"$m",History_Q!$G$2:$G$1000,"populated")<>1,COUNTIFS(History_Q!$C$2:$C$1000,"revenue",History_Q!$B$2:$B$1000,(SUMIFS(History_Q!$B$2:$B$1000,History_Q!$A$2:$A$1000,G$6,History_Q!$C$2:$C$1000,"revenue")-4),History_Q!$E$2:$E$1000,"$m",History_Q!$G$2:$G$1000,"populated")<>1,SUMIFS(History_Q!$D$2:$D$1000,History_Q!$C$2:$C$1000,"revenue",History_Q!$B$2:$B$1000,(SUMIFS(History_Q!$B$2:$B$1000,History_Q!$A$2:$A$1000,G$6,History_Q!$C$2:$C$1000,"revenue")-4),History_Q!$E$2:$E$1000,"$m",History_Q!$G$2:$G$1000,"populated")=0),"",SUMIFS(History_Q!$D$2:$D$1000,History_Q!$C$2:$C$1000,"revenue",History_Q!$B$2:$B$1000,(SUMIFS(History_Q!$B$2:$B$1000,History_Q!$A$2:$A$1000,G$6,History_Q!$C$2:$C$1000,"revenue")),History_Q!$E$2:$E$1000,"$m",History_Q!$G$2:$G$1000,"populated")/SUMIFS(History_Q!$D$2:$D$1000,History_Q!$C$2:$C$1000,"revenue",History_Q!$B$2:$B$1000,(SUMIFS(History_Q!$B$2:$B$1000,History_Q!$A$2:$A$1000,G$6,History_Q!$C$2:$C$1000,"revenue")-4),History_Q!$E$2:$E$1000,"$m",History_Q!$G$2:$G$1000,"populated")-1) | H11: =IF(OR(H$6="",COUNTIFS(History_Q!$C$2:$C$1000,"revenue",History_Q!$B$2:$B$1000,(SUMIFS(History_Q!$B$2:$B$1000,History_Q!$A$2:$A$1000,H$6,History_Q!$C$2:$C$1000,"revenue")),History_Q!$E$2:$E$1000,"$m",History_Q!$G$2:$G$1000,"populated")<>1,COUNTIFS(History_Q!$C$2:$C$1000,"revenue",History_Q!$B$2:$B$1000,(SUMIFS(History_Q!$B$2:$B$1000,History_Q!$A$2:$A$1000,H$6,History_Q!$C$2:$C$1000,"revenue")-4),History_Q!$E$2:$E$1000,"$m",History_Q!$G$2:$G$1000,"populated")<>1,SUMIFS(History_Q!$D$2:$D$1000,History_Q!$C$2:$C$1000,"revenue",History_Q!$B$2:$B$1000,(SUMIFS(History_Q!$B$2:$B$1000,History_Q!$A$2:$A$1000,H$6,History_Q!$C$2:$C$1000,"revenue")-4),History_Q!$E$2:$E$1000,"$m",History_Q!$G$2:$G$1000,"populated")=0),"",SUMIFS(History_Q!$D$2:$D$1000,History_Q!$C$2:$C$1000,"revenue",History_Q!$B$2:$B$1000,(SUMIFS(History_Q!$B$2:$B$1000,History_Q!$A$2:$A$1000,H$6,History_Q!$C$2:$C$1000,"revenue")),History_Q!$E$2:$E$1000,"$m",History_Q!$G$2:$G$1000,"populated")/SUMIFS(History_Q!$D$2:$D$1000,History_Q!$C$2:$C$1000,"revenue",History_Q!$B$2:$B$1000,(SUMIFS(History_Q!$B$2:$B$1000,History_Q!$A$2:$A$1000,H$6,History_Q!$C$2:$C$1000,"revenue")-4),History_Q!$E$2:$E$1000,"$m",History_Q!$G$2:$G$1000,"populated")-1) | I11: =IF(OR(I$6="",COUNTIFS(History_Q!$C$2:$C$1000,"revenue",History_Q!$B$2:$B$1000,(SUMIFS(History_Q!$B$2:$B$1000,History_Q!$A$2:$A$1000,I$6,History_Q!$C$2:$C$1000,"revenue")),History_Q!$E$2:$E$1000,"$m",History_Q!$G$2:$G$1000,"populated")<>1,COUNTIFS(History_Q!$C$2:$C$1000,"revenue",History_Q!$B$2:$B$1000,(SUMIFS(History_Q!$B$2:$B$1000,History_Q!$A$2:$A$1000,I$6,History_Q!$C$2:$C$1000,"revenue")-4),History_Q!$E$2:$E$1000,"$m",History_Q!$G$2:$G$1000,"populated")<>1,SUMIFS(History_Q!$D$2:$D$1000,History_Q!$C$2:$C$1000,"revenue",History_Q!$B$2:$B$1000,(SUMIFS(History_Q!$B$2:$B$1000,History_Q!$A$2:$A$1000,I$6,History_Q!$C$2:$C$1000,"revenue")-4),History_Q!$E$2:$E$1000,"$m",History_Q!$G$2:$G$1000,"populated")=0),"",SUMIFS(History_Q!$D$2:$D$1000,History_Q!$C$2:$C$1000,"revenue",History_Q!$B$2:$B$1000,(SUMIFS(History_Q!$B$2:$B$1000,History_Q!$A$2:$A$1000,I$6,History_Q!$C$2:$C$1000,"revenue")),History_Q!$E$2:$E$1000,"$m",History_Q!$G$2:$G$1000,"populated")/SUMIFS(History_Q!$D$2:$D$1000,History_Q!$C$2:$C$1000,"revenue",History_Q!$B$2:$B$1000,(SUMIFS(History_Q!$B$2:$B$1000,History_Q!$A$2:$A$1000,I$6,History_Q!$C$2:$C$1000,"revenue")-4),History_Q!$E$2:$E$1000,"$m",History_Q!$G$2:$G$1000,"populated")-1) | ... M11: =IF(OR(M$6="",COUNTIFS(History_Q!$C$2:$C$1000,"revenue",History_Q!$B$2:$B$1000,(SUMIFS(History_Q!$B$2:$B$1000,History_Q!$A$2:$A$1000,M$6,History_Q!$C$2:$C$1000,"revenue")),History_Q!$E$2:$E$1000,"$m",History_Q!$G$2:$G$1000,"populated")<>1,COUNTIFS(History_Q!$C$2:$C$1000,"revenue",History_Q!$B$2:$B$1000,(SUMIFS(History_Q!$B$2:$B$1000,History_Q!$A$2:$A$1000,M$6,History_Q!$C$2:$C$1000,"revenue")-4),History_Q!$E$2:$E$1000,"$m",History_Q!$G$2:$G$1000,"populated")<>1,SUMIFS(History_Q!$D$2:$D$1000,History_Q!$C$2:$C$1000,"revenue",History_Q!$B$2:$B$1000,(SUMIFS(History_Q!$B$2:$B$1000,History_Q!$A$2:$A$1000,M$6,History_Q!$C$2:$C$1000,"revenue")-4),History_Q!$E$2:$E$1000,"$m",History_Q!$G$2:$G$1000,"populated")=0),"",SUMIFS(History_Q!$D$2:$D$1000,History_Q!$C$2:$C$1000,"revenue",History_Q!$B$2:$B$1000,(SUMIFS(History_Q!$B$2:$B$1000,History_Q!$A$2:$A$1000,M$6,History_Q!$C$2:$C$1000,"revenue")),History_Q!$E$2:$E$1000,"$m",History_Q!$G$2:$G$1000,"populated")/SUMIFS(History_Q!$D$2:$D$1000,History_Q!$C$2:$C$1000,"revenue",History_Q!$B$2:$B$1000,(SUMIFS(History_Q!$B$2:$B$1000,History_Q!$A$2:$A$1000,M$6,History_Q!$C$2:$C$1000,"revenue")-4),History_Q!$E$2:$E$1000,"$m",History_Q!$G$2:$G$1000,"populated")-1)
A12: Margins
A13: Gross margin % | B13: =IF(OR(B262="",B9="",B9=0),"",B262/B9) | C13: =IF(OR(C262="",C9="",C9=0),"",C262/C9) | D13: =IF(OR(D262="",D9="",D9=0),"",D262/D9) | E13: =IF(OR(E262="",E9="",E9=0),"",E262/E9) | F13: =IF(OR(F262="",F9="",F9=0),"",F262/F9) | G13: =IF(OR(G262="",G9="",G9=0),"",G262/G9) | H13: =IF(OR(H262="",H9="",H9=0),"",H262/H9) | I13: =IF(OR(I262="",I9="",I9=0),"",I262/I9) | ... M13: =IF(OR(M262="",M9="",M9=0),"",M262/M9)
A14: Operating margin % | B14: =IF(OR(B32="",B9="",B9=0),"",B32/B9) | C14: =IF(OR(C32="",C9="",C9=0),"",C32/C9) | D14: =IF(OR(D32="",D9="",D9=0),"",D32/D9) | E14: =IF(OR(E32="",E9="",E9=0),"",E32/E9) | F14: =IF(OR(F32="",F9="",F9=0),"",F32/F9) | G14: =IF(OR(G32="",G9="",G9=0),"",G32/G9) | H14: =IF(OR(H32="",H9="",H9=0),"",H32/H9) | I14: =IF(OR(I32="",I9="",I9=0),"",I32/I9) | ... M14: =IF(OR(M32="",M9="",M9=0),"",M32/M9)
